Workbook
Name _15SMGDF: #REF!
Name _25SMGDF: #REF!
Name _3SMGDF: #REF!
Name _A67000: #REF!
Name _A69000: #REF!
Name _CLF1: #REF!
Name _msoanchor_1: #REF!
Name _msoanchor_3: #REF!
Name _Toc100142032: #REF!
Name _Toc100142033: #REF!
Name _Toc100142034: #REF!
Name _Toc100142035: #REF!
Name _Toc100142036: #REF!
Name _Toc100142037: #REF!
Name _Toc100142038: #REF!
Name _Toc100142039: #REF!
Name _Toc100142041: #REF!
Name _Toc100142043: #REF!
Name _Toc100142044: #REF!
Name _Toc100142045: #REF!
Name _Toc100142046: #REF!
Name _Toc100142047: #REF!
Name _Toc100142048: #REF!
Name _Toc99981304: #REF!
Name _Toc99981308: #REF!
Name _Toc99981317: #REF!
Name AAAAAAAA: #REF!
Name Absenteeism: #REF!
Name ACCDEPR: #REF!
Name AccountVP: #REF!
Name ACCRCOMP: #REF!
Name ACCRINCTX: #REF!
Name ACCRINT: #REF!
Name ACCRPAY: #REF!
Name ACCRPRLIAB: #REF!
Name ACCRPSLIAB: #REF!
Name ACCRTXLIAB: #REF!
Name ad: #REF!
Name ADSLSRECBLE: #REF!
Name allocations: #REF!
Name Amex_BO: #REF!
Name AMS: #REF!
Name Annual_Hours: #REF!
Name AnnualVolume_1: #REF!
Name AP: #REF!
Name Arsenal: #REF!
Name Arsenal2: #REF!
Name asdd: #REF!
Name auxiliar: #REF!
Name av: #REF!
Name Avg_Weeks_in_month: 52/12
Name AvgConcurrency: #REF!
Name b: #REF!
Name Badge_Type: #REF!
Name Bal_Sheet_99_01: #REF!
Name balance: #REF!
Name bandedstaff: #REF!
Name bandedstaffdescriptions: #REF!
Name BandMappings: #REF!
Name BandMappingsLookup: #REF!

Sheet updated version-relationship
J1: 100 | M1: Working Capital Efficiency (%)
B2: Sub LOB | C2: L0 | D2: L1 | E2: L2 | F2: Intervention | G2: Use Case | H2: Final Intervention | I2: Impact definition | J2: H
B3: P2P | C3: Cash Conversion Cycle (Days) | D3: Days Payable Outstanding (DPO) | E3: Invoice processing cycle time | F3: Intelligent Document Processing | G3: Uses OCR + AI to auto-extract, validate, and process invoices, POs , and contracts | H3: Intelligent Document Processing: Auto-extract Invoice Fields, Automate Journal Entry Capture, Digitize Supplier Invoices | I3: reduce | J3: 0.1
B4: P2P | C4: Cash Conversion Cycle (Days) | D4: Days Payable Outstanding (DPO) | E4: Invoice processing cycle time | F4: RPA bots | G4: Automated PO Generation and Routing | H4: RPA Bots: Automate PO Generation and Payment Reminders, Validate PO's and Contracts | I4: reduce | J4: 0.2
B5: P2P | C5: Cash Conversion Cycle (Days) | D5: Days Payable Outstanding (DPO) | E5: Invoice processing cycle time | F5: Workflow Automation | G5: Standardizes invoice approvals and expense management with automated routing | H5: Workflow Automation: Standardize Invoice Approvals, Vendor Onboarding, Purchase Requests | I5: reduce | J5: 0.15
B6: P2P | C6: Cash Conversion Cycle (Days) | D6: Days Payable Outstanding (DPO) | E6: First-Time Match Rate | F6: RPA bots | G6: Straight-through Payment Automation | H6: RPA Bots: Automate PO Generation and Payment Reminders, Validate PO's and Contracts | I6: increase | J6: 0.2
B7: P2P | C7: Cash Conversion Cycle (Days) | D7: Days Payable Outstanding (DPO) | E7: First-Time Match Rate | F7: Intelligent Document Processing | G7: Uses OCR + AI to auto-extract, validate, and process invoices, POs , and contracts | H7: Intelligent Document Processing: Auto-extract Invoice Fields, Automate Journal Entry Capture, Digitize Supplier Invoices | I7: increase | J7: 0.2
B8: P2P | C8: Cash Conversion Cycle (Days) | D8: Days Payable Outstanding (DPO) | E8: PO policy compliance rate | F8: RPA bots | G8: Intelligent Rule Based Enforcement for Policies | H8: RPA Bots: Automate PO Generation and Payment Reminders, Validate PO's and Contracts | I8: increase | J8: 0.2
B9: P2P | C9: Cost Efficiency (%) | D9: Cost per Invoice | E9: % of automated invoices | F9: RPA bots | G9: Automated PO Generation and Routing | H9: RPA Bots: Automate PO Generation and Payment Reminders, Validate PO's and Contracts | I9: increase | J9: 0.2
B10: P2P | C10: Cost Efficiency (%) | D10: Cost per Invoice | E10: % of automated invoices | F10: Workflow Automation | G10: Standardizes invoice approvals and expense management with automated routing | H10: Workflow Automation: Standardize Invoice Approvals, Vendor Onboarding, Purchase Requests | I10: increase | J10: 0.15
B11: P2P | C11: Cost Efficiency (%) | D11: Cost per Invoice | E11: Productvity/Employee | F11: Process Mining for Procurement Gaps | G11: Process Mining for Procurement Gaps | H11: Process Mining: Detect Procurement Gaps, Optimize Close Timelines, Identify Collection Bottlenecks | I11: increase | J11: 0.15
B12: P2P | C12: Cost Efficiency (%) | D12: Cost per Invoice | F12: Data Visualization & Real-time Dashboards | G12: Supplier Dashboards & Reporting | H12: Data Visualization & Real-time Dashboards: Track Receivables in Real-Time, Monitor Financial KPIs, Analyze Spend Patterns | J12: Na
B13: R2R | C13: - | D13: Compliance with Month-end Schedule | E13: Timeliness of journal entries | F13: Streamlined Reporting Workflows | G13: Intelligent Rule Based Enforcement for Policies | H13: Workflow Automation: Standardize Invoice Approvals, Vendor Onboarding, Purchase Requests | I13: increase | J13: 0.15
B14: R2R | C14: - | D14: Compliance with Month-end Schedule | E14: % of Automated journal entries | F14: Data entry and error remediation with RPA | H14: RPA Bots: Automate PO Generation and Payment Reminders, Validate PO's and Contracts | I14: increase | J14: 0.2
B15: R2R | C15: - | D15: Accuracy of Financial Reports | E15: Accuracy of journal entries | F15: Enterprise analysis for audits and compliance | H15: Analytics: Predictive Analytics Engine for Collections, Cash-flow Forecast, Compliance & Audit Analysis | I15: increase | J15: 0.15
B16: R2R | C16: - | D16: Accuracy of Financial Reports | E16: Reconciliation accuracy | F16: Auto-matching and Exception Handling | H16: RPA Bots: Automate PO Generation and Payment Reminders, Validate PO's and Contracts | I16: increase | J16: 0.2
B17: I2C | C17: Cash Conversion Cycle (Days) | D17: Days Sales Outstanding (DSO) | E17: Invoice Processing Cycle Time | F17: Unified CRM Solution to Automate Workflows | H17: Workflow Automation: Standardize Invoice Approvals, Vendor Onboarding, Purchase Requests | I17: reduce | J17: 0.15
B18: I2C | C18: Cash Conversion Cycle (Days) | D18: Days Sales Outstanding (DSO) | E18: First-Time Match Rate | F18: Intelligent Document Processing | H18: Intelligent Document Processing: Auto-extract Invoice Fields, Automate Journal Entry Capture, Digitize Supplier Invoices | I18: increase | J18: 0.2
B19: I2C | C19: Cash Conversion Cycle (Days) | D19: Days Sales Outstanding (DSO) | E19: Collection efficiency | F19: AI/ML-led forecasting | G19: Enhances cash flow predictions, supply and demand-based forecasting | H19: Workflow Automation: Standardize Invoice Approvals, Vendor Onboarding, Purchase Requests | I19: increase | J19: 0.15
B20: I2C | C20: Cash Conversion Cycle (Days) | D20: Bad Debt Ratio | E20: Collection efficiency | F20: Predictive Analytics Engine for Collections | H20: Analytics: Predictive Analytics Engine for Collections, Cash-flow Forecast, Compliance & Audit Analysis | I20: increase | J20: 0.15
B21: I2C | C21: Cash Conversion Cycle (Days) | D21: Collection efficiency | E21: Invoice Accuracy | F21: Automated Routing for Invoice/Expense Mgt. | H21: RPA Bots: Automate PO Generation and Payment Reminders, Validate PO's and Contracts | I21: increase | J21: 0.2
B22: I2C | C22: Cash Conversion Cycle (Days) | D22: Collection efficiency | E22: Timely Follow-Up | F22: RPA Automated Follow-up | G22: RPA | H22: RPA Bots: Automate PO Generation and Payment Reminders, Validate PO's and Contracts | I22: increase | J22: 0.2
B23: I2C | C23: Cost Efficiency (%) | D23: Cost per Invoice | E23: % of automated invoices | F23: RPA bots | G23: Automated PO Generation and Routing | H23: RPA Bots: Automate PO Generation and Payment Reminders, Validate PO's and Contracts | I23: increase | J23: 0.2
B24: I2C | C24: Cost Efficiency (%) | D24: Cost per Invoice | E24: % of automated invoices | F24: Workflow Automation | G24: Standardizes invoice approvals with automated routing | H24: Workflow Automation: Standardize Invoice Approvals, Vendor Onboarding, Purchase Requests | I24: increase | J24: 0.15
B25: I2C | C25: Cost Efficiency (%) | D25: Cost per Invoice | E25: Productvity/Employee | F25: Process Mining for Efficiency Savings | H25: Process Mining: Detect Procurement Gaps, Optimize Close Timelines, Identify Collection Bottlenecks | I25: increase | J25: 0.15
H26: AI/ML-led forecasting
D28: impactfactorIPCTDSO | E28: 0.4
D30: currentDSO
D31: ImpactIPCT | E31: change in IPCT * 0.4 | F31: Intelligent Document Processing | G31: Auto-extract Invoice Fields, Automate Journal Entry Capture, Digitize Supplier Invoices
D32: impactFTMR | E32: change*0.4 | F32: RPA Bots | G32: Automate PO Generation and Payment Reminders, Validate PO's and Contracts
D33: total impaft | E33: IPCT+FTMR | F33: Workflow Automation | G33: Standardize Invoice Approvals, Vendor Onboarding, Purchase Requests
D34: new DSO | E34: CUrrentDSO*impactIPCT | F34: Process Mining | G34: Detect Procurement Gaps, Optimize Close Timelines, Identify Collection Bottlenecks
F35: Data Visualization & Real-time Dashboards | G35: Track Receivables in Real-Time, Monitor Financial KPIs, Analyze Spend Patterns
F37: AI/ML | G37: AI/ML-led forecasting
F38: Analytics | G38: Predictive Analytics Engine for Collections
C43: Aesthetics inputs
C44: TP logo | D44: <div style="position: absolute; top: 6px; right: 10px;"> <svg width="50" height="43" viewBox="0 0 40 53" fill="none" xmlns="http://www.w3.org/2000/svg"> <path d="M9.64912 9.98551H0C0 10.2928 0.239234 10.5232 0.478469 10.7536C3.18979 13.3652 6.9378 16.9754 9.64912 19.587C9.80861 19.7406 10.0478 19.587 10.0478 19.4333V10.3696C10.0478 10.1391 9.88836 9.98551 9.64912 9.98551ZM31.7384 0H31.0207V8.98696C31.0207 9.52464 30.5423 9.98551 29.984 9.98551H21.2919C21.0526 9.98551 20.8931 10.1391 20.8931 10.3696V43.3217C20.8931 43.8594 20.4147 44.3203 19.8565 44.3203H11.244C11.0048 44.3203 10.8453 44.6275 11.0048 44.7812C12.9187 46.6246 16.6667 50.2348 18.5805 52.0783C19.059 52.5391 19.7767 53 20.6539 53H28.9474C29.7448 53 30.3828 52.3855 30.3828 51.6174V33.029C30.3828 32.7986 30.5423 32.6449 30.7815 32.6449H31.6587C40.9888 32.6449 50 27.1913 50 16.2841C50 5.37681 43.1419 0 31.7384 0Z" fill="white"/> </svg> </div>
C45: Font | D45: font-family: 'Calibri Light', 'Calibri', sans-serif;
C46: Title box colour | D46: #4A4C6A
C47: Button colour | D47: #D8D9E4
...

Sheet Sheet1
A1: Requirements
A2: Default values for all metrics / interventions to be defined
A3: Default values to be updated for metrics in the event drag function OR intervention impact is triggered
A4: Each calculation for metric manipulation to consider mentioned parameters
A5: IMPACTING METRICS
A6: Current Value
A7: New Value
A8: Delta Value
A9: Impact Factor (associated with IMPACTED METRIC)
A10: IMPACTED METRICS
A11: Default Value
A12: Updated Value
... A19: Dependency map to be added

Sheet Level-wise Parameters
B1: Business Outcomes | F1: L1 Metrics | J1: L2 Metrics | N1: Interventions
B2: Business Outcomes | C2: Definition | D2: Benchmarking Range | F2: Service Line | G2: L1 Metrics | H2: Benchmarking Range | J2: Service Line | K2: L2 Metrics | L2: Benchmarking Range | N2: Interventions | O2: Value Range
D3: Low | E3: High | H3: Low | I3: High | L3: Low | M3: High | O3: Low | P3: High
B4: Cash Conversion Cycle (Days) | C4: The time (in days) it takes for a company to convert its investments in inventory and other resources into cash flow from sales A lower CCC indicates faster cash flow turnover and improved liquidity | D4: 0 | E4: 30 | F4: [Invoice to Cash] | G4: Days Sales Outstanding (DSO) | H4: 0 days | I4: 30 days | J4: [Invoice to Cash] | K4: Invoice Processing Time (AR) | L4: 0 days | M4: 5 days | N4: ICR led scanning and indexing | O4: 0 | P4: 0.15
F5: [Invoice to Cash] | G5: Collection Effectiveness Index (CEI) | H5: 0.8 | I5: 1 | J5: [Invoice to Cash] | K5: First-Time Match Rate (AR) | L5: 0.9 | M5: 1 | N5: Data entry and error remediation with RPA | O5: 0 | P5: 0.15
B6: Working Capital Efficiency (%) | C6: How effectively a company manages its short-term assets and liabilities to sustain operations while optimizing liquidity A higher WCE reflects better financial health and operational efficiency | D6: 0.05 | E6: 0.1 | F6: [Record to Report] | G6: Time to Close | H6: 0 days | I6: 5 days | J6: [Invoice to Cash] | K6: Bad Debt Ratio | L6: 0 | M6: 0.03 | N6: [Analytics] Predictive cash forecasting to forecast Collection Trends + Cash Flow | O6: 0 | P6: 0.15
F7: [Record to Report] | G7: Audit Findings | H7: 0 | I7: 1 | J7: [Invoice to Cash] | K7: Cost per Invoice | L7: $0 | M7: $5 | N7: [AI] AI/ML driven AP | O7: 0 | P7: 0.15
B8: Cost Efficiency (% of revenue) | C8: The percentage of revenue spent on operational costs, assessing how well a company controls expenses while maintaining profitability A lower cost percentage indicates improved financial performance and better resource utilization | D8: 0.8 | E8: 1 | F8: [Procure to Pay] | G8: Days Payable Outstanding (DPO) | H8: 0 | I8: 45 | J8: [Invoice to Cash] | K8: Cash Flow Forecast Accuracy | L8: 0.95 | M8: 1 | N8: [AI] AI cash application to match payments to invoices in real-time | O8: 0 | P8: 0.15
F9: [Procure to Pay] | G9: Cost per purchase order | H9: 0 | I9: 4 | J9: [Record to Report] | K9: Error Rate | L9: 0 | M9: 0.01 | N9: [Analytics] Enterprise analysis for audits and compliance | O9: 0 | P9: 0.15
J10: [Record to Report] | K10: Process Compliance Rate | L10: 0.95 | M10: 1
A11: Service Line | B11: L1 | C11: L2 | J11: [Record to Report] | K11: Automation Rate | L11: 0.8 | M11: 1
A12: Invoice to Cash | B12: Days Sales Outstanding (DSO) | C12: Invoice Processing Time, First-Time Match Rate | J12: [Record to Report] | K12: Reconciliation Accuracy | L12: 0.99 | M12: 1
B13: Collection Effectiveness Index (CEI) | C13: Bad Debt Ratio, Cost per Invoice, Cash Flow Forecast Accuracy | J13: [Procure to Pay] | K13: Invoice Processing Time (AP) | L13: 0 days | M13: 5 days
A14: Record to Report | B14: Time to Close | C14: Error rate, Process Compliance rate, Automation rate | J14: [Procure to Pay] | K14: First-Time Match Rate (AP) | L14: 0.9 | M14: 1
B15: Audit Findings | C15: Reconciliation accuracy, Process Compliance Rate | J15: [Procure to Pay] | K15: On-time Payment Rate | L15: 0.95 | M15: 1
A16: Procure to Pay | B16: DPO | C16: Invoice Processing Time, First-Time Match Rate, On-time payment rate | J16: [Procure to Pay] | K16: Policy Compliance Rate | L16: 0.95 | M16: 1
B17: Cost per purchase order | C17: Policy Compliance Rate, On-time Payment Rate

Sheet Interventions impacting L2
C1: Invoice Processing Time (AR) | D1: First-Time Match Rate (AR) | E1: Bad Debt Ratio | F1: Cost per Invoice | G1: Cash Flow Forecast Accuracy | H1: Error Rate | I1: Process Compliance Rate | J1: Automation Rate | K1: Reconciliation Accuracy | L1: Invoice Processing Time (AP) | M1: First-Time Match Rate (AP) | N1: On-time Payment Rate | O1: Policy Compliance Rate
B2: Net Impact>> | C2: =SUM(C7,C9,C11,C13,C15,C17) -> -0.0999 | D2: =SUM(D7,D9,D11,D13,D15,D17) -> 0.1 | E2: =SUM(E7,E9,E11,E13,E15,E17) -> -0.1 | F2: =SUM(F7,F9,F11,F13,F15,F17) -> -0.0999 | G2: =SUM(G7,G9,G11,G13,G15,G17) -> 0.1 | H2: =SUM(H7,H9,H11,H13,H15,H17) -> -0.1 | I2: =SUM(I7,I9,I11,I13,I15,I17) -> 0.1 | J2: =SUM(J7,J9,J11,J13,J15,J17) -> 0.0999 | ... O2: =SUM(O7,O9,O11,O13,O15,O17) -> 0.1
B3: Current Value | C3: 7 | D3: 0.5 | E3: 0.04 | F3: 4 | G3: 0.85 | J3: 0.5 | L3: 9 | M3: 0.5
B4: Best-in class | C4: 5 | D4: 50%-60% | E4: 0 - 2% | F4: $3 - $4 | G4: 90% - 100% | I4: 90% - 100% | J4: 50% - 60% | L4: 6 - 9 days | M4: 50%-60%
B5: Updated value | C5: =C3*(1+C2) -> 6.3007 | D5: =IF(D3*(1+D2)<=100%,D3*(1+D2),1) -> 0.55 | E5: =IF(E3*(1+E2)<=100%,E3*(1+E2),1) -> 0.036 | F5: =F3+(F3*F2) -> 3.6004 | G5: =IF(G3*(1+G2)<=100%,G3*(1+G2),1) -> 0.935 | J5: =IF(J3*(1+J2)<=100%,J3*(1+J2),1) -> 0.54995 | L5: =L3*(1+L2) -> 8.1009 | M5: =IF(M3*(1+M2)<=100%,M3*(1+M2),1) -> 0.55
A6: ICR led scanning and indexing | C6: TRUE | D6: FALSE | E6: FALSE | F6: TRUE | G6: FALSE | H6: FALSE | I6: FALSE | J6: FALSE | K6: FALSE | L6: TRUE | M6: FALSE | N6: FALSE | O6: FALSE
B7: Impact % | C7: -0.0333 | F7: -0.0333 | L7: -0.0333
A8: Data entry and error remediation with RPA | C8: TRUE | D8: TRUE | E8: FALSE | F8: TRUE | G8: FALSE | H8: TRUE | I8: FALSE | J8: TRUE | K8: FALSE | L8: TRUE | M8: TRUE | N8: FALSE | O8: FALSE
C9: -0.0333 | D9: 0.05 | F9: -0.0333 | H9: -0.05 | J9: 0.0333 | L9: -0.0333 | M9: 0.05
A10: [Analytics] Predictive cash forecasting to forecast Collection Trends + Cash Flow | C10: FALSE | D10: FALSE | E10: TRUE | F10: FALSE | G10: TRUE | H10: FALSE | I10: FALSE | J10: FALSE | K10: FALSE | L10: FALSE | M10: FALSE | N10: FALSE | O10: FALSE
E11: -0.1 | G11: 0.1
A12: [AI] AI/ML driven AP | C12: FALSE | D12: FALSE | E12: FALSE | F12: FALSE | G12: FALSE | H12: FALSE | I12: FALSE | J12: TRUE | K12: FALSE | L12: TRUE | M12: TRUE | N12: TRUE | O12: FALSE
J13: 0.0333 | L13: -0.0333 | M13: 0.05 | N13: 0.1
A14: [AI] AI cash application to match payments to invoices in real-time | C14: TRUE | D14: TRUE | E14: FALSE | F14: TRUE | G14: FALSE | H14: FALSE | I14: FALSE | J14: TRUE | K14: TRUE | L14: FALSE | M14: FALSE | N14: FALSE | O14: FALSE
C15: -0.0333 | D15: 0.05 | F15: -0.0333 | J15: 0.0333 | K15: 0.05
A16: [Analytics] Enterprise analysis for audits and compliance | C16: FALSE | D16: FALSE | E16: FALSE | F16: FALSE | G16: FALSE | H16: TRUE | I16: TRUE | J16: FALSE | K16: TRUE | L16: FALSE | M16: FALSE | N16: FALSE | O16: TRUE
H17: -0.05 | I17: 0.1 | K17: 0.05 | O17: 0.1
C21: Invoice Processing Cycle Time (AR) | E21: Invoice Processing Cycle Time (AR)
C22: First-Time Match Rate (AR) | E22: First-Time Match Rate (AR)
C23: Collection Efficiency | E23: Collection Efficiency
C24: Invoice Accuracy (AR) | E24: Invoice Accuracy (AR)
C28: Timely Follow-Up | E28: Timely Follow-Up
C32: % of Automated Invoices (AR) | E32: % of Automated Invoices (AR)
C36: Productivity / Employee (AR) | E36: Productivity / Employee (AR)
C40: Timeliness of Journal Entries | E40: Timeliness of Journal Entries
C44: % of Automated Journal Entries | E44: % of Automated Journal Entries
C48: Accuracy of Journal Entries | E48: Accuracy of Journal Entries
C52: Reconciliation Accuracy | E52: Reconciliation Accuracy
C56: Invoice Processing Cycle Time (AP) | E56: Invoice Processing Cycle Time (AP)
... C72: Productivity / Employee (AP) | E72: Productivity / Employee (AP)

Sheet Relationships (L2 impacting L1)
D1: I2C | H1: R2R | J1: P2P
C2: L1 Metrics>> | D2: Days Sales Outstanding (DSO) | E2: Bad Debt Ratio | F2: Collection Efficiency | G2: Cost per Invoice (AR) | H2: Compliance with Month-end Schedule | I2: Accuracy of Financial Reports | J2: Days Payable Outstanding (DPO) | K2: Invoice Processing Cycle-Time | L2: Cost per Invoice (AP)
C3: Net Impact>> | D3: =SUM(D10,D14,D18,D22,D30,D34,D38,D42,D46,D50,D54,D58,D62) -> -0.25 | E3: =SUM(E10,E14,E18,E22,E30,E34,E38,E42,E46,E50,E54,E58,E62) -> -0.05 | F3: =SUM(F10,F14,F18,F22,F30,F34,F38,F42,F46,F50,F54,F58,F62,F26) -> -0.16666667 | G3: =SUM(G10,G14,G18,G22,G30,G34,G38,G42,G46,G50,G54,G58,G62) -> -0.25 | H3: =SUM(H38,H42) -> 0.112 | I3: =SUM(I10,I14,I18,I22,I30,I34,I38,I42,I46,I50,I54,I58,I62) -> 0.24 | J3: =SUM(J10,J14,J18,J22,J30,J34,J38,J42,J46,J50,J54,J58,J62) -> -0.1 | L3: =SUM(L10,L14,L18,L22,L30,L34,L38,L42,L46,L50,L54,L58,L62,L66,L70) -> -0.25
C4: Current Value | D4: 45 | E4: 0.02 | F4: 0.7 | G4: 5 | H4: 0.8 | I4: 0.04 | J4: 65 | L4: 5
C5: Best-in class | D5: 30 - 45 days | E5: 0% - 2% | F5: 80% - 85% | G5: $3 - $4 | H5: 95-100% | I5: 3% - 5% | J5: 45 - 60 days | L5: $3 - $4
B6: L2 Metrics | C6: Updated value | D6: =D4+(D4*D3) -> 33.75 | E6: =E4*(1+E3) -> 0.019 | F6: =F4*(1-F3) -> 0.81666667 | G6: =G4+(G4*G3) -> 3.75 | H6: =H4*(1+H3) -> 0.8896 | I6: =I4*(1+I3) -> 0.0496 | J6: =J4+(J4*J3) -> 58.5 | L6: =L4+(L4*L3) -> 3.75
B7: Invoice Processing Cycle Time (AR) | C7: IPTAR | D7: TRUE | E7: FALSE | F7: FALSE | G7: FALSE | H7: FALSE | I7: FALSE | J7: FALSE | K7: FALSE | L7: FALSE
C8: Impact Factor | D8: =10/15 -> 0.66666667
C9: Change in IPTAR % | D9: -0.15
C10: Impact to DSO % | D10: =D8*D9 -> -0.1
B11: First-Time Match Rate (AR) | C11: FTMRAR | D11: TRUE | E11: FALSE | F11: FALSE | G11: FALSE | H11: FALSE | I11: FALSE | J11: FALSE | K11: FALSE | L11: FALSE
C12: Impact Factor | D12: =10/15 -> 0.66666667
C13: Change % | D13: 0.15
C14: Impact % | D14: =-D13*D12 -> -0.1
B15: Collection Efficiency | C15: CE | D15: TRUE | E15: TRUE | F15: FALSE | G15: FALSE | H15: FALSE | I15: FALSE | J15: FALSE | K15: FALSE | L15: FALSE
C16: Impact Factor | D16: =5/10 -> 0.5 | E16: =5/10 -> 0.5
C17: Change % | D17: 0.1 | E17: 0.1
C18: Impact % | D18: =-D17*D16 -> -0.05 | E18: =-E17*E16 -> -0.05
B19: Invoice Accuracy (AR) | C19: IAAR | D19: FALSE | E19: FALSE | F19: TRUE | G19: FALSE | H19: FALSE | I19: FALSE | J19: FALSE | K19: FALSE | L19: FALSE
C20: Impact Factor | F20: =10/15 -> 0.66666667
C21: Change % | F21: 0.1
C22: Impact % | F22: =-F21*F20 -> -0.066666667
B23: Timely Follow-Up | C23: IAAR | D23: FALSE | E23: FALSE | F23: TRUE | G23: FALSE | H23: FALSE | I23: FALSE | J23: FALSE | K23: FALSE | L23: FALSE
C24: Impact Factor | F24: 0.66666667
C25: Change % | F25: 0.15
C26: Impact % | F26: =-F25*F24 -> -0.1
B27: % of Automated Invoices (AR) | C27: AIAR | D27: FALSE | E27: FALSE | F27: FALSE | G27: TRUE | H27: FALSE | I27: FALSE | J27: FALSE | K27: FALSE | L27: FALSE
C28: Impact Factor | G28: =20/30 -> 0.66666667
C29: Change % | G29: 0.3
C30: Impact % | G30: =-G29*G28 -> -0.2
B31: Productivity / Employee (AR) | C31: PEAR | D31: FALSE | E31: FALSE | F31: FALSE | G31: TRUE | H31: FALSE | I31: FALSE | J31: FALSE | K31: FALSE | L31: FALSE
C32: Impact Factor | G32: =5/10 -> 0.5
C33: Change % | G33: 0.1
C34: Impact % | G34: =-G33*G32 -> -0.05
B35: Timeliness of Journal Entries | C35: TJE | D35: FALSE | E35: FALSE | F35: FALSE | G35: FALSE | H35: TRUE | I35: FALSE | J35: FALSE | K35: FALSE | L35: FALSE
C36: Impact Factor | H36: 0.8
C37: Change % | H37: 0.04
C38: Impact % | H38: =H37*H36 -> 0.032
B39: % of Automated Journal Entries | C39: AJE | D39: FALSE | E39: FALSE | F39: FALSE | G39: FALSE | H39: TRUE | I39: FALSE | J39: FALSE | K39: FALSE | L39: FALSE
C40: Impact Factor | H40: 0.8
...

Sheet Relationships (L1 impacting BO)
C1: L0>> | D1: Cash Conversion Cycle (Days) | E1: Working Capital Efficiency (%) | F1: Cost Efficiency (% of revenue)
C2: Current Value | D2: 45 | E2: 0.1 | F2: 0
C3: Best-in class | D3: 30 | E3: 0.15 | F3: -
C4: Updated value | D4: =D2+(D2*D5) -> 32.625 | E4: =E2*(1+E5) -> 0.10164 | F4: =F2+F5 -> -0.2
B5: L1 Metrics | C5: Net Impact>> | D5: =SUM(D9,D13,D17,D21,D25,D29) -> -0.275 | E5: =SUM(E9,E13,E17,E21,E25,E29) -> 0.0164 | F5: =SUM(F9,F13,F17,F21,F25,F29,F33,F37) -> -0.2
B6: Days Sales Outstanding (DSO) | C6: DSO | D6: TRUE | E6: TRUE | F6: FALSE
C7: Impact Factor | D7: 0.7 | E7: 0.4
C8: Change % | D8: ='Relationships (L2 impacting L1)'!D3 -> -0.25 | E8: ='Relationships (L2 impacting L1)'!D3 -> -0.25
C9: Impact % | D9: =D8*D7 -> -0.175 | E9: =-E8*E7 -> 0.1
B10: Bad Debt Ratio | C10: BDR | D10: FALSE | E10: FALSE | F10: FALSE
C11: Impact Factor
C12: Change %
C13: Impact %
B14: Collection Efficiency | C14: CE | D14: TRUE | E14: TRUE | F14: FALSE
C15: Impact Factor | D15: 0.6 | E15: 0.3
C16: Change % | D16: ='Relationships (L2 impacting L1)'!F3 -> -0.16666667 | E16: ='Relationships (L2 impacting L1)'!H3 -> 0.112
C17: Impact % | D17: =D16*D15 -> -0.1 | E17: =-E16*E15 -> -0.0336
B18: Cost per Invoice (AR) | C18: CPIAR | D18: FALSE | E18: FALSE | F18: TRUE
C19: Impact Factor | F19: 0.4
C20: Change % | F20: ='Relationships (L2 impacting L1)'!G3 -> -0.25
C21: Impact % | F21: =F20*F19 -> -0.1
B22: Compliance with Month-end Schedule | C22: CMS | D22: FALSE | E22: TRUE | F22: FALSE
C23: Impact Factor | E23: 0.5
C24: Change % | E24: ='Relationships (L2 impacting L1)'!J3 -> -0.1
C25: Impact % | E25: =E23*E24 -> -0.05
B26: Accuracy of Financial Reports | C26: AFR | D26: FALSE | E26: FALSE | F26: FALSE
C27: Impact Factor
C28: Change %
C29: Impact %
B30: Days Payable Outstanding (DPO) | C30: DPO | D30: TRUE | E30: FALSE | F30: FALSE
C31: Impact Factor | D31: 0.3
C32: Change % | D32: 0.15
C33: Impact % | D33: =-D32*D31 -> -0.045
B34: Cost per Invoice (AP) | C34: CPIAP | D34: FALSE | E34: FALSE | F34: TRUE
C35: Impact Factor | F35: 0.4
C36: Change % | F36: ='Relationships (L2 impacting L1)'!L3 -> -0.25
C37: Impact % | F37: =F36*F35 -> -0.1

Sheet Metric IDs
A2: Level | B2: Metrics | D2: Slider ID | E2: Triangle | F2: Value
A3: L2 | B3: Invoice Processing Time (AR) | C3: IPT | D3: l2-metrics-ipt | E3: l2-triangle-ipt | F3: l2-value-ipt
A4: L2 | B4: First-Time Match Rate (AR) | C4: FTMRAR | D4: l2-metrics-bar | E4: l2-triangle-bar | F4: l2-value-bar
A5: L2 | B5: Bad Debt Ratio | C5: BDR | D5: l2-metrics-cffa | E5: l2-triangle-cffa | F5: l2-value-cffa
A6: L2 | B6: Cost per Invoice | C6: CPI | D6: other-metrics-spct | E6: triangle-spct | F6: value-spct
A7: L2 | B7: Cash Flow Forecast Accuracy | C7: CFA | D7: other-metrics-apipt | E7: triangle-apipt | F7: value-apipt
A8: L2 | B8: Error Rate | C8: ERR | D8: other-metrics-sccr | E8: triangle-sccr | F8: value-sccr
A9: L2 | B9: Process Compliance Rate | C9: PCR | D9: other-metrics-ofct | E9: triangle-ofct | F9: value-ofct
A10: L2 | B10: Automation Rate | C10: AMR | D10: other-metrics-idrt | E10: triangle-idrt | F10: value-idrt
A11: L2 | B11: Reconciliation Accuracy | C11: RNA | D11: other-metrics-arw | E11: triangle-arw | F11: value-arw
A12: L2 | B12: Invoice Processing Time (AP) | C12: IPTAP | D12: other-metrics-jea | E12: triangle-jea | F12: value-jea
A13: L2 | B13: First-Time Match Rate (AP) | C13: FTMRAP | D13: other-metrics-bsrt | E13: triangle-bsrt | F13: value-bsrt
A14: L2 | B14: On-time Payment Rate | C14: OTPR | D14: other-metrics-icrt | E14: triangle-icrt | F14: value-icrt
... A21: L1 | B21: Cost per purchase order | C21: CPPO | D21: l1-metrics-cppo | E21: l1-triangle-cppo | F21: l1-value-cppo
A22: Interventions | B22: ICR led scanning and indexing | D22: intervention-icr | F22: icr-value-display
A23: Interventions | B23: Data entry and error remediation with RPA | D23: intervention-rpa | F23: rpa-value-display
A24: Interventions | B24: [Analytics] Predictive cash forecasting to forecast Collection Trends + Cash Flow | D24: intervention-ai-cash-app | F24: ai-cash-app-value-display
A25: Interventions | B25: [AI] AI/ML driven AP | D25: intervention-cash-forecast | F25: cash-forecast-value-display
A26: Interventions | B26: [AI] AI cash application to match payments to invoices in real-time | D26: intervention-ai-ap | F26: ai-ap-value-display
A27: Interventions | B27: [Analytics] Enterprise analysis for audits and compliance | D27: intervention-analytics | F27: analytics-value-display

Sheet Metrics Mapping
A1: OUTCOME | G1: L1 | M1: L2 | U1: INTERVENTIONS
A2: Overall Business Outcome | B2: Business Outcomes (L0) | C2: Baseline Values | D2: Updated Values | E2: Benchmarking Values (L0) | G2: Impact to Business Outcome | H2: L1 Metrics | I2: Baseline Values | J2: Updated Values | K2: Benchmarking Values (L1) | M2: Impact (from L2) | P2: L2 Metrics | Q2: Baseline Values | R2: Updated Values | S2: Benchmarking Values (L2) | U2: Impact on L2 (from interventions) | Y2: Intervention 1 | Z2: Intervention 2 | AA2: Intervention 3
B3: L0 | E3: Low ¬ | F3: ®High | K3: Low ¬ | L3: ®High | M3: Total Impact on L1 | N3: Impact on L1 | O3: ¬Change in L2 | S3: Low ¬ | T3: ®High | U3: Cumulative | V3: Intervention 1 | W3: Intervention 2 | X3: Intervention 3
A4: Cash Flow Improvement | B4: Cash Conversion Cycle (CCC) | E4: 30 days | F4: 45 days | G4: DIO+DSO-DPO | H4: DSO | K4: 30 days | L4: 45 days | M4: ΔDSO=(ΔInvoice Processing Time/Total Credit Sales per Day) + ((Change in Disputed Invoice Amount*×Resolution Time)/Total Credit Sales per Day) - ((Early Collections/Total Credit Sales per Day) * 30)) | N4: ΔDSO= Total Credit Sales per Day /Change in Invoice Processing Time | O4: =U4 -> -0.062 | P4: Invoice Processing Time | S4: 1 day | T4: 2 days | U4: =V4+W4+X4 -> -0.062 | V4: -0.007 | W4: -0.005 | X4: -0.05 | Y4: ICR led scanning and indexing | Z4: Data entry and error remediation with RPA | AA4: [AI] AI cash application to match payments to invoices in real-time
N5: ΔDSO= (Total Credit Sales per Day / Disputed Invoice Amount)*Average Resolution Time | P5: Billing Accuracy Rate | S5: 0.9 | T5: 0.95 | Y5: Data entry and error remediation with RPA | Z5: [AI] AI cash application to match payments to invoices in real-time
N6: ΔDSO= Total Credit Sales per Day Additional Early Collections ​ | P6: Cash Flow Forecast Accuracy | S6: 0.9 | T6: 0.95 | Y6: [Analytics] Predictive cash forecasting to forecast Collection Trends + Cash Flow
H7: DPO | K7: 45 days | L7: 60 days | P7: Supplier Payment Cycle Time | Y7: [AI] AI/ML driven AP
P8: AP Invoice Processing Time | S8: 6 days | T8: 9 days | Y8: ICR led scanning and indexing | Z8: Data entry and error remediation with RPA | AA8: [AI] AI cash application to match payments to invoices in real-time
P9: Supplier Contract Compliance Rate | S9: 0.95 | T9: 0.99 | Y9: [AI] AI/ML driven AP | Z9: [Analytics] Enterprise analysis for audits and compliance
H10: Collection Effectiveness Index (CEI) | K10: 0.85 | L10: 1 | P10: Billing Accuracy Rate | Y10: Data entry and error remediation with RPA | Z10: [AI] AI cash application to match payments to invoices in real-time
P11: Invoice Dispute Resolution Time | S11: 7 days | T11: 14 days | Y11: ICR led scanning and indexing | Z11: Data entry and error remediation with RPA
P12: AR Write-offs % | S12: 0 | T12: 0.02 | Y12: [AI] AI cash application to match payments to invoices in real-time | Z12: [Analytics] Predictive cash forecasting to forecast Collection Trends + Cash Flow
H13: Financial Close Cycle Time (Monthly) | K13: 5 days | L13: 7 days | P13: Journal Entry Accuracy | S13: 0.9 | T13: 0.95 | Y13: [AI] AI cash application to match payments to invoices in real-time
P14: Balance Sheet Reconciliation Time | Y14: [Analytics] Enterprise analysis for audits and compliance
P15: Intercompany Reconciliation Time | Y15: [Analytics] Enterprise analysis for audits and compliance
B16: Working Capital | H16: DSO | K16: 30 days | L16: 45 days | P16: Invoice Processing Time | S16: 1 day | T16: 2 days | Y16: ICR led scanning and indexing | Z16: Data entry and error remediation with RPA | AA16: [AI] AI cash application to match payments to invoices in real-time
P17: Billing Accuracy Rate | S17: 0.9 | T17: 0.95 | Y17: Data entry and error remediation with RPA | Z17: [AI] AI cash application to match payments to invoices in real-time
H18: DPO | K18: 45 days | L18: 60 days | P18: Supplier Payment Cycle Time | Y18: [AI] AI/ML driven AP
P19: AP Invoice Processing Time | S19: 6 days | T19: 9 days | Y19: ICR led scanning and indexing | Z19: Data entry and error remediation with RPA | AA19: [AI] AI cash application to match payments to invoices in real-time
P20: Cost per Invoice Processed | S20: $3 | T20: $4 | Y20: [AI] AI/ML driven AP
H21: DIO | P21: Order Fulfillment Cycle Time | Y21: [AI] AI/ML driven AP
H22: Working Capital Turnover | P22: AR Write-offs % | S22: 0 | T22: 0.02 | Y22: [AI] AI cash application to match payments to invoices in real-time | Z22: [Analytics] Predictive cash forecasting to forecast Collection Trends + Cash Flow
A23: Cost Efficiency | B23: Net Profit / Income P/E Ratio | H23: AP Processing Cost | P23: Supplier Contract Compliance Rate | Y23: [AI] AI/ML driven AP | Z23: [Analytics] Enterprise analysis for audits and compliance
P24: AP Invoice Processing Time | S24: 6 days | T24: 9 days | Y24: ICR led scanning and indexing | Z24: Data entry and error remediation with RPA | AA24: [AI] AI cash application to match payments to invoices in real-time
P25: Cost per Invoice Processed | S25: $3 | T25: $4 | Y25: [AI] AI/ML driven AP
H26: AR Processing Cost | P26: Billing Accuracy Rate | S26: 0.9 | T26: 0.95 | Y26: Data entry and error remediation with RPA | Z26: [AI] AI cash application to match payments to invoices in real-time
P27: Invoice Processing Time | S27: 1 day | T27: 2 days | Y27: ICR led scanning and indexing | Z27: Data entry and error remediation with RPA | AA27: [AI] AI cash application to match payments to invoices in real-time
H28: Financial Closing Cost (dependent on Cycle Time) | P28: Journal Entry Accuracy | S28: 0.9 | T28: 0.95 | Y28: [AI] AI cash application to match payments to invoices in real-time
P29: Balance Sheet Reconciliation Time | Y29: [Analytics] Enterprise analysis for audits and compliance
P30: Intercompany Reconciliation Time | Y30: [Analytics] Enterprise analysis for audits and compliance

Sheet Update
H1: Interventions
B2: Business Outcomes | C2: Service Line | D2: L1 | E2: Benchmark | F2: L2 | G2: Benchmark
B3: Cash Flow (Cash Conversion Cycle) | C3: Invoice to Cash | D3: Days Sales Outstanding (DSO) | E3: <30 days | F3: Invoice Processing Time | G3: <5 days
F4: First-Time Match Rate | G4: >=90%
D5: Collection Effectiveness Index (CEI) | E5: >=80% | F5: Bad Debt Ratio | G5: <3%
F6: Cost per Invoice | G6: $2.81
B7: Working Capital Efficiency | F7: Cash Flow Forecast Accuracy | G7: >=95%
C8: Record to Report | D8: Time to Close | E8: 5-10 days | F8: Error rate | G8: <5%
F9: Process Compliance rate | G9: >=90%
F10: Automation rate | G10: >=80%
D11: Audit Findings | E11: <=2 | F11: Reconciliation accuracy | G11: >=90%
F12: Process Compliance Rate | G12: >=90%
B13: Cost Efficiency | C13: Procure to Pay | D13: Days Payable Outstanding (DPO) | E13: <45 days | F13: Invoice Processing Time | G13: <5 days
F14: First-Time Match Rate | G14: >=90%
F15: On-time payment rate | G15: >=90%
D16: Cost per purchase order | E16: $50-$150 | F16: Policy Compliance Rate | G16: >=90%
F17: On-time Payment Rate | G17: >=90%

Sheet Mind Map

Sheet Assumptions
B1: Business Outcomes (L0) | D1: L1 Metrics | E1: Formulae | F1: L2 Metrics | G1: Impact Logic | H1: Assumptions for calculations
B2: L0
B3: Cash Conversion Cycle (CCC) | D3: DSO | E3: DSO = (Accounts Receivable (AR)/Total Credit Sales)*Number of Days | F3: Invoice Processing Time | G3: Invoice Processing Time primarily impacts AR because a delay in invoicing means a delay in collecting payments If Invoice Processing Time decreases by X%, then the AR should decrease proportionally (assuming all other factors remain constant) | H3: None Inversely proportional. Direct % impact
F4: Billing Accuracy Rate | G4: If invoices contain errors, corrections and disputes delay payment collection A higher Billing Accuracy Rate reduces Invoice Dispute Rate, leading to faster collections and lower AR | H4: None Inversely proportional. Direct % impact
F5: Cash Flow Forecast Accuracy | G5: Cash Flow Forecast Accuracy (CFFA) impacts cash flow planning and collection strategies If forecasting is accurate, businesses can plan proactive collections, reducing AR If forecasting is inaccurate, businesses may be caught off guard, leading to higher AR and increased DSO | H5: Direct impact cannot be acertained. Dependency on payment terms, credit policy, industry specific factors, customer base, macroeconomic factors etc.
D6: DPO | E6: DPO=(AP/COGS)*Number of days | F6: Supplier Payment Cycle Time | G6: SPCT directly affects Accounts Payable (AP): If SPCT increases, AP increases (since payments are delayed) If SPCT decreases, AP decreases (since payments are made faster) Since DPO is directly proportional to AP, any change in SPCT will proportionally impact DPO | H6: None Directly proportional. Direct % impact
F7: Supplier Contract Compliance Rate | G7: Higher SCCR means suppliers adhere better to agreed payment terms, reducing unexpected early payments or penalties. This helps maintain or extend DPO if favorable terms are utilized Lower SCCR can lead to shorter DPO due to forced early payments, penalties, or disruptions in payment scheduling | H7: No direct relationship to ascertain % impact
D8: DIO | E8: DIO = (Inventory/COGS)*Number of days Inventory=Daily Demand*OFCT | F8: Order Fulfillment Cycle Time | G8: Order Fulfillment Cycle Time is the total time taken from receiving an order to delivering it A longer OFCT leads to slower inventory turnover, increasing DIO A shorter OFCT leads to faster inventory movement, decreasing DIO | H8: Assuming an inversely proportional relationship
D9: Collection Effectiveness Index (CEI) | E9: CEI = ({Beginning AR + Credit Sales - Ending AR Total} / {Beginning AR + Credit Sales - Ending AR current})v* 100 | F9: Billing Accuracy Rate | G9: Billing Accuracy Rate impacting Ending AR current (X% increase in accuracy to provide Y% reduction in errors leading to Y% reduction in Ending AR current) | H9: Impact dependent on relative values of Beginning AR, Credit Sales and ending AR
F10: Aged AR % | G10: Ending AR Total represents overdue receivables, which are part of Aged AR % Aged AR % Increases → CEI Decreases Aged AR % Decreases → CEI Increases | H10: Impact dependent on relative values of Beginning AR, Credit Sales and ending AR
D11: Financial Close Cycle Time | E11: Journal Entry Time + Balance Sheet Reconciliation Time + Intercompany Reconciliation Time | F11: Journal Entry Accuracy | G11: Direct correlation with Journal Entry Time | H11: Impact based on relative values of Balance Sheet Reconciliation Time and Intercompany Reconciliation Time
F12: Balance Sheet Reconciliation Time | H12: Impact based on relative values of Journal Entry Time and Intercompany Reconciliation Time
F13: Intercompany Reconciliation Time | H13: Impact based on relative values of Journal Entry Time and Balance Sheet Reconciliation Time
B14: Working Capital | D14: DSO | F14: Invoice Processing Time
F15: Billing Accuracy Rate
D16: DPO | F16: Supplier Payment Cycle Time
F17: Cost per Invoice Processed
D18: DIO | F18: Order Fulfillment Cycle Time
D19: Working Capital Turnover | E19: WCT=Revenue (Net sales) / Working Capital Working Capital = Current Assets - Current Liabilities | F19: Aged AR % | G19: A higher Aged AR % means slower collections, leading to higher AR balances and lower cash availability AR is part of Current Assets, an increase in AR leads to higher Working Capital, which reduces WCT | H19: Impact based on relative values of Revenue and Current Liabilities
B20: Net Profit / Income P/E Ratio | D20: AP Processing Cost | F20: Supplier Contract Compliance Rate
F21: Cost per Invoice Processed
D22: AR Processing Cost | F22: Billing Accuracy Rate
F23: Invoice Processing Time
C24: Cost of Finance & Admin Operations reduces by Y% Errors and Adjustments reduce, preventing losses of Z% Net Profit increases by (Y% + Z%) | D24: Financial Closing Cost (dependent on Cycle Time) | E24: Journal Entry Time + Balance Sheet Reconciliation Time + Intercompany Reconciliation Time | F24: Journal Entry Accuracy | G24: Direct correlation with Journal Entry Time | H24: Impact based on relative values of Balance Sheet Reconciliation Time and Intercompany Reconciliation Time
F25: Balance Sheet Reconciliation Time | H25: Impact based on relative values of Journal Entry Time and Intercompany Reconciliation Time
F26: Intercompany Reconciliation Time | H26: Impact based on relative values of Journal Entry Time and Balance Sheet Reconciliation Time
